<?xml version="1.0"?>
<robot name="car">
    <link name="base_link">
        <inertial>
        <origin xyz="0 0 0.5"  rpy="0 0 0 "/>
        <mass value="1"/>
        <inertia ixx="100" ixy="0" ixz="0"
                 iyy="100" iyz="0" izz="100"/>
        </inertial>
        <visual>
            <origin xyz="0 0 0.5" rpy="0 0 0"/>
            <geometry>
            <box size="0.5 2 0.5"/>
            </geometry>
            <material name="silver">
            <color rgba="0.5 0.8 0.6 1.0"/>
            </material>
        </visual>
        <colsion>
        </colsion>
    </link>
    <joint name="left_wheel" type="continuous">
        <parent link="base_link"/>
        <child link="left_wheel"/>
        <origin xyz="0.35 1 0.25"  rpy="1.57 0.0 0.0"/>
        <axis rpy="0 0 0" xyz="0.2 0 0"/>
    </joint>
    <link name="left_wheel">
        <inertial>
            <origin xyz="0 0 0" rpy="0 0 0"/>
            <mass value="0.2"/>
            <inertia ixx="100" ixy="0" ixz="0"
                     iyy="100" iyz="0" izz="100"/>
        </inertial>
        <visual>
            <origin xyz="0.35 1 0.25" rpy="1.5708 0 1.5708"/>
            <geometry>
                <cylinder length="0.2" radius="0.2"/>
                <material name="rubber">
                    <color rgba="0 0 0 1"/>
                </material>
            </geometry>
        </visual>
    </link>


</robot>